<?xml version="1.0"?>
<robot name="lynxmotion_arm" xmlns:xacro="http://ros.org/wiki/xacro">
	<xacro:property name="params" value="${load_yaml('../../shared/config/servo_config.yaml')}"/>
	
	<xacro:arg name="world_pos" default="0 0 0"/>

	<xacro:property name="base_link_mass" value="0.1" />
	<xacro:property name="base_link_length" value="0.04" />
	<xacro:property name="base_link_radius" value="0.095" />
	<xacro:property name="base_link_origin_xyz" value="0 0 0.02" />
	<xacro:property name="base_link_origin_rpy" value="0 0 0" />

	<xacro:property name="turret_mass" value="0.2" />
	<xacro:property name="turret_length" value="0.005" />
	<xacro:property name="turret_radius" value="0.095" />
	<xacro:property name="turret_origin_xyz" value="0 0 0" />
	<xacro:property name="turret_origin_rpy" value="0 0 0" />

	<xacro:property name="upperarm_mass" value="0.2" />
	<xacro:property name="upperarm_width" value="0.02" />
	<xacro:property name="upperarm_height" value="0.08" />
	<xacro:property name="upperarm_depth" value="0.18" />
	<xacro:property name="upperarm_origin_xyz" value="0 0 0.09" />
	<xacro:property name="upperarm_origin_rpy" value="0 0 0" />

	<xacro:property name="forearm_mass" value="0.2" />
	<xacro:property name="forearm_length" value="0.2" />
	<xacro:property name="forearm_radius" value="0.015" />
	<xacro:property name="forearm_origin_xyz" value="0 0 0.10" />
	<xacro:property name="forearm_origin_rpy" value="0 0 0" />

	<xacro:property name="wrist_mass" value="0.1" />
	<xacro:property name="wrist_width" value="0.02" />
	<xacro:property name="wrist_height" value="0.05" />
	<xacro:property name="wrist_depth" value="0.06" />
	<xacro:property name="wrist_origin_xyz" value="0 0 0.03" />
	<xacro:property name="wrist_origin_rpy" value="0 0 0" />
	
	<xacro:property name="hand_mass" value="0.02" />
	<xacro:property name="hand_width" value="0.02" />
	<xacro:property name="hand_height" value="0.07" />
	<xacro:property name="hand_depth" value="0.025" />
	<xacro:property name="hand_origin_xyz" value="0 0 0.0125" />
	<xacro:property name="hand_origin_rpy" value="0 0 0" />
	
	<xacro:property name="gripper_mass" value="0.01" />
	<xacro:property name="gripper_width" value="0.02" />
	<xacro:property name="gripper_height" value="0.02" />
	<xacro:property name="gripper_depth" value="0.03" />
	<xacro:property name="gripper_origin_xyz" value="0 0 0.015" />
	<xacro:property name="gripper_origin_rpy" value="0 0 0" />

	<xacro:macro name="collision_cylinder" params="mass length radius xyz rpy">
		<collision>
		    <geometry>
			<cylinder length="${length}" radius="${radius}" />
		    </geometry>	
		</collision>
		<origin xyz="${xyz}" rpy="${rpy}" />
		<inertial>
		    <mass value="${mass}"/>
		    <inertia ixx="${(1/12)*mass*(3*radius*radius + length*length)}" ixy="0.0" ixz="0.0" iyy="${(1/12)*mass*(3*radius*radius + length*length)}" iyz="0.0" izz="${0.5*mass*radius*radius}"/>
		</inertial>
	</xacro:macro>

	<xacro:macro name="collision_box" params="mass width height depth xyz rpy">
		<collision>
		    <geometry>
			<box size="${width} ${height} ${depth}" />
		    </geometry>	
		</collision>
		<origin xyz="${xyz}" rpy="${rpy}" />
		<inertial>
		    <mass value="${mass}"/>
		    <inertia ixx="${(1/12)*mass*(height*height + depth*depth)}" ixy="0.0" ixz="0.0" iyy="${(1/12)*mass*(width*width + depth*depth)}" iyz="0.0" izz="${(1/12)*mass*(width*width + height*height)}"/>
		</inertial>
	</xacro:macro>

	<link name="world">		
	</link>
    <link name="base_link">
        <visual>
            <geometry>
                <cylinder length="${base_link_length}" radius="${base_link_radius}" />
            </geometry>
            <material name="black">
                <!--<color rgba="0 0 0 1" />-->
            </material>
            <origin xyz="${base_link_origin_xyz	}" rpy="${base_link_origin_rpy}" />
        </visual>
	<xacro:collision_cylinder mass="${base_link_mass}" length="${base_link_length}" radius="${base_link_radius}" xyz="${base_link_origin_xyz}" rpy="${base_link_origin_rpy}"/>
    </link>
    <link name="turret">
        <visual>
            <geometry>
                <cylinder length="${turret_length}" radius="${turret_radius}" />
            </geometry>
            <material name="black" />
        </visual>
	<xacro:collision_cylinder mass="${turret_mass}" length="${turret_length}" radius="${turret_radius}" xyz="${turret_origin_xyz}" rpy="${turret_origin_rpy}"/>
    </link>
    <link name="upperarm">
        <visual>
            <geometry>			
                <box size="${upperarm_width} ${upperarm_height} ${upperarm_depth}" />
            </geometry>
            <material name="black" />
            <origin xyz="${upperarm_origin_xyz}" rpy="${upperarm_origin_rpy}" />
        </visual>
	<xacro:collision_box mass="${upperarm_mass}" width="${upperarm_width}" height="${upperarm_height}" depth="${upperarm_depth}" xyz="${upperarm_origin_xyz}" rpy="${upperarm_origin_rpy}"/>	
    </link>
    <link name="forearm" >
        <visual>
            <geometry>
                <cylinder length="${forearm_length}" radius="${forearm_radius}" />
            </geometry>
            <material name="silver" >
                <color rgba="0.9 0.9 0.9 1" />
            </material>
            <origin xyz="${forearm_origin_xyz}" rpy="${forearm_origin_rpy}" />
        </visual>
	<xacro:collision_cylinder mass="${forearm_mass}" length="${forearm_length}" radius="${forearm_radius}" xyz="${forearm_origin_xyz}" rpy="${forearm_origin_rpy}"/>
    </link>
    <link name="wrist">
        <visual>
            <geometry>			
                <box size="${wrist_width} ${wrist_height} ${wrist_depth}" />
            </geometry>
            <material name="black" />
            <origin xyz="${wrist_origin_xyz}" rpy="${wrist_origin_rpy}" />
        </visual>
	<xacro:collision_box mass="${wrist_mass}" width="${wrist_width}" height="${wrist_height}" depth="${wrist_depth}" xyz="${wrist_origin_xyz}" rpy="${wrist_origin_rpy}"/>	
    </link>
    <link name="hand">
        <visual>
            <geometry>
                <box size="${hand_width} ${hand_height} ${hand_depth}" />
            </geometry>
            <material name="black" />
            <origin xyz="${hand_origin_xyz}" rpy="${hand_origin_rpy}" />
        </visual>
        <xacro:collision_box mass="${hand_mass}" width="${hand_width}" height="${hand_height}" depth="${hand_depth}" xyz="${hand_origin_xyz}" rpy="${hand_origin_rpy}"/>	
    </link>
    <link name="gripper_left">
        <visual>
            <geometry>
                <box size="${gripper_width} ${gripper_height} ${gripper_depth}" />
            </geometry>
            <origin xyz="${gripper_origin_xyz}" rpy="${gripper_origin_rpy}" />
            <material name="green" >
                <color rgba="0 1 0 1" />
            </material>
        </visual>
        <xacro:collision_box mass="${gripper_mass}" width="${gripper_width}" height="${gripper_height}" depth="${gripper_depth}" xyz="${gripper_origin_xyz}" rpy="${gripper_origin_rpy}"/>	
    </link>
    <link name="gripper_right">
        <visual>
            <geometry>
                <box size="${gripper_width} ${gripper_height} ${gripper_depth}" />
            </geometry>
            <origin xyz="${gripper_origin_xyz}" rpy="${gripper_origin_rpy}" />
            <material name="green" />
        </visual>
        <xacro:collision_box mass="${gripper_mass}" width="${gripper_width}" height="${gripper_height}" depth="${gripper_depth}" xyz="${gripper_origin_xyz}" rpy="${gripper_origin_rpy}"/>	
    </link>
       
    <joint name="world2base_link" type="fixed">
    	<parent link="world" />
    	<child link="base_link" />
    	<origin xyz="$(arg world_pos)" rpy="0 0 0" />
    </joint>   
    <joint name="base_link2turret" type="revolute">
        <parent link="base_link" />
        <child link="turret" />
        <origin xyz="0 0 0.045" rpy="0 0 0" />
        <limit effort="1000.0" lower="${(params['servos']['base'][2]) * pi / 180}" upper="${(params['servos']['base'][3]) * pi / 180}" velocity="0.5" />
        <axis xyz="0 0 1" />
    </joint>
    <joint name="turret2upperarm" type="revolute">
        <parent link="turret" />
        <child link="upperarm" />
        <origin xyz="0 0 0.02" rpy="0 -1.57 0" />
        <limit effort="1000.0" lower="${(params['servos']['shoulder'][2]) * pi / 180}" upper="${(params['servos']['shoulder'][3]) * pi / 180}" velocity="0.5" />
        <axis xyz="0 1 0" />
    </joint>
    <joint name="upperarm2forearm" type="revolute">
        <parent link="upperarm" />
        <child link="forearm" />
        <origin xyz="0 0 0.18" rpy="0 0 0" />
        <limit effort="1000.0" lower="${(params['servos']['elbow'][2]) * pi / 180}" upper="${(params['servos']['elbow'][3]) * pi / 180}" velocity="0.5" />
        <axis xyz="0 1 0" />
    </joint>
    <joint name="forearm2wrist" type="continuous">
        <parent link="forearm" />
        <child link="wrist" />
        <origin xyz="0 0 0.20" rpy="0 0 0" />
        <axis xyz="0 -1 0" />
    </joint>
    <joint name="wrist2hand" type="continuous">
        <parent link="wrist" />
        <child link="hand" />
        <origin xyz="0 0 0.06" rpy="0 0 0" />
        <axis xyz="0 0 1" />
    </joint>
    <joint name="gripper_left2hand" type="prismatic">
        <parent link="hand" />
        <child link="gripper_left" />
        <origin xyz="0 0.025 0.025" rpy="0 0 0" />
        <limit effort="1000.0" lower="${params['sim_servos']['gripper'][1]}" upper="${params['sim_servos']['gripper'][2]}" velocity="0.5" />
        <axis xyz="0 -1 0" />
    </joint>
    <joint name="gripper_right2hand" type="prismatic">
        <parent link="hand" />
        <child link="gripper_right" />
        <origin xyz="0 -0.025 0.025" rpy="0 0 0" />
        <limit effort="1000.0" lower="${params['sim_servos']['gripper'][2]}" upper="${params['sim_servos']['gripper'][1]}" velocity="0.5" />
        <axis xyz="0 1 0" />
        <mimic joint="gripper_left2hand" multiplier="1" offset="0"/>
    </joint>
    
    <link name="grip_point">
    </link>  
    <joint name="hand2grip_point" type="fixed">
        <parent link="hand" />
        <child link="grip_point" />
        <origin xyz="0 0 0.05" rpy="0 1.57 0" />
        <axis xyz="0 1 0" />
    </joint>
</robot>
